[2024-03-21T19:42:34.113-0300] {taskinstance.py:1090} INFO - Dependencies all met for dep_context=non-requeueable deps ti=<TaskInstance: executing_multiple_tasks3.task_A manual__2024-03-21T22:42:32.503150+00:00 [queued]>
[2024-03-21T19:42:34.117-0300] {taskinstance.py:1090} INFO - Dependencies all met for dep_context=requeueable deps ti=<TaskInstance: executing_multiple_tasks3.task_A manual__2024-03-21T22:42:32.503150+00:00 [queued]>
[2024-03-21T19:42:34.117-0300] {taskinstance.py:1288} INFO - 
--------------------------------------------------------------------------------
[2024-03-21T19:42:34.118-0300] {taskinstance.py:1289} INFO - Starting attempt 1 of 1
[2024-03-21T19:42:34.118-0300] {taskinstance.py:1290} INFO - 
--------------------------------------------------------------------------------
[2024-03-21T19:42:34.130-0300] {taskinstance.py:1309} INFO - Executing <Task(BashOperator): task_A> on 2024-03-21 22:42:32.503150+00:00
[2024-03-21T19:42:34.132-0300] {standard_task_runner.py:55} INFO - Started process 2694 to run task
[2024-03-21T19:42:34.134-0300] {standard_task_runner.py:82} INFO - Running: ['airflow', 'tasks', 'run', 'executing_multiple_tasks3', 'task_A', 'manual__2024-03-21T22:42:32.503150+00:00', '--job-id', '42', '--raw', '--subdir', 'DAGS_FOLDER/multiple_tasks3.py', '--cfg-path', '/tmp/tmputfbuh79']
[2024-03-21T19:42:34.135-0300] {standard_task_runner.py:83} INFO - Job 42: Subtask task_A
[2024-03-21T19:42:34.189-0300] {task_command.py:389} INFO - Running <TaskInstance: executing_multiple_tasks3.task_A manual__2024-03-21T22:42:32.503150+00:00 [running]> on host DESKTOP-0DNP0LN.localdomain
[2024-03-21T19:42:34.209-0300] {abstractoperator.py:615} ERROR - Exception rendering Jinja template for task 'task_A', field 'bash_command'. Template: 'task_A.sh'
Traceback (most recent call last):
  File "/home/carlosfalcone/.local/lib/python3.7/site-packages/airflow/models/abstractoperator.py", line 607, in _do_render_template_fields
    seen_oids,
  File "/home/carlosfalcone/.local/lib/python3.7/site-packages/airflow/models/abstractoperator.py", line 659, in render_template
    template = jinja_env.get_template(value)
  File "/home/carlosfalcone/.local/lib/python3.7/site-packages/jinja2/environment.py", line 1010, in get_template
    return self._load_template(name, globals)
  File "/home/carlosfalcone/.local/lib/python3.7/site-packages/jinja2/environment.py", line 969, in _load_template
    template = self.loader.load(self, name, self.make_globals(globals))
  File "/home/carlosfalcone/.local/lib/python3.7/site-packages/jinja2/loaders.py", line 126, in load
    source, filename, uptodate = self.get_source(environment, name)
  File "/home/carlosfalcone/.local/lib/python3.7/site-packages/jinja2/loaders.py", line 218, in get_source
    raise TemplateNotFound(template)
jinja2.exceptions.TemplateNotFound: task_A.sh
[2024-03-21T19:42:34.210-0300] {taskinstance.py:1776} ERROR - Task failed with exception
Traceback (most recent call last):
  File "/home/carlosfalcone/.local/lib/python3.7/site-packages/airflow/models/taskinstance.py", line 1383, in _run_raw_task
    self._execute_task_with_callbacks(context, test_mode)
  File "/home/carlosfalcone/.local/lib/python3.7/site-packages/airflow/models/taskinstance.py", line 1502, in _execute_task_with_callbacks
    task_orig = self.render_templates(context=context)
  File "/home/carlosfalcone/.local/lib/python3.7/site-packages/airflow/models/taskinstance.py", line 2123, in render_templates
    original_task.render_template_fields(context)
  File "/home/carlosfalcone/.local/lib/python3.7/site-packages/airflow/models/baseoperator.py", line 1179, in render_template_fields
    self._do_render_template_fields(self, self.template_fields, context, jinja_env, set())
  File "/home/carlosfalcone/.local/lib/python3.7/site-packages/airflow/utils/session.py", line 75, in wrapper
    return func(*args, session=session, **kwargs)
  File "/home/carlosfalcone/.local/lib/python3.7/site-packages/airflow/models/abstractoperator.py", line 607, in _do_render_template_fields
    seen_oids,
  File "/home/carlosfalcone/.local/lib/python3.7/site-packages/airflow/models/abstractoperator.py", line 659, in render_template
    template = jinja_env.get_template(value)
  File "/home/carlosfalcone/.local/lib/python3.7/site-packages/jinja2/environment.py", line 1010, in get_template
    return self._load_template(name, globals)
  File "/home/carlosfalcone/.local/lib/python3.7/site-packages/jinja2/environment.py", line 969, in _load_template
    template = self.loader.load(self, name, self.make_globals(globals))
  File "/home/carlosfalcone/.local/lib/python3.7/site-packages/jinja2/loaders.py", line 126, in load
    source, filename, uptodate = self.get_source(environment, name)
  File "/home/carlosfalcone/.local/lib/python3.7/site-packages/jinja2/loaders.py", line 218, in get_source
    raise TemplateNotFound(template)
jinja2.exceptions.TemplateNotFound: task_A.sh
[2024-03-21T19:42:34.213-0300] {taskinstance.py:1332} INFO - Marking task as FAILED. dag_id=executing_multiple_tasks3, task_id=task_A, execution_date=20240321T224232, start_date=20240321T224234, end_date=20240321T224234
[2024-03-21T19:42:34.224-0300] {standard_task_runner.py:105} ERROR - Failed to execute job 42 for task task_A (task_A.sh; 2694)
[2024-03-21T19:42:34.226-0300] {local_task_job.py:212} INFO - Task exited with return code 1
[2024-03-21T19:42:34.239-0300] {taskinstance.py:2596} INFO - 0 downstream tasks scheduled from follow-on schedule check
