[2024-03-23T21:00:04.624-0300] {taskinstance.py:1090} INFO - Dependencies all met for dep_context=non-requeueable deps ti=<TaskInstance: cross_task_communication2.increment_by_1 scheduled__2024-03-23T00:00:00+00:00 [queued]>
[2024-03-23T21:00:04.629-0300] {taskinstance.py:1090} INFO - Dependencies all met for dep_context=requeueable deps ti=<TaskInstance: cross_task_communication2.increment_by_1 scheduled__2024-03-23T00:00:00+00:00 [queued]>
[2024-03-23T21:00:04.629-0300] {taskinstance.py:1288} INFO - 
--------------------------------------------------------------------------------
[2024-03-23T21:00:04.629-0300] {taskinstance.py:1289} INFO - Starting attempt 1 of 1
[2024-03-23T21:00:04.629-0300] {taskinstance.py:1290} INFO - 
--------------------------------------------------------------------------------
[2024-03-23T21:00:04.640-0300] {taskinstance.py:1309} INFO - Executing <Task(PythonOperator): increment_by_1> on 2024-03-23 00:00:00+00:00
[2024-03-23T21:00:04.641-0300] {standard_task_runner.py:55} INFO - Started process 7469 to run task
[2024-03-23T21:00:04.643-0300] {standard_task_runner.py:82} INFO - Running: ['airflow', 'tasks', 'run', 'cross_task_communication2', 'increment_by_1', 'scheduled__2024-03-23T00:00:00+00:00', '--job-id', '99', '--raw', '--subdir', 'DAGS_FOLDER/cross_task_communication2.py', '--cfg-path', '/tmp/tmpn0p5m2ob']
[2024-03-23T21:00:04.643-0300] {standard_task_runner.py:83} INFO - Job 99: Subtask increment_by_1
[2024-03-23T21:00:04.675-0300] {task_command.py:389} INFO - Running <TaskInstance: cross_task_communication2.increment_by_1 scheduled__2024-03-23T00:00:00+00:00 [running]> on host DESKTOP-0DNP0LN.localdomain
[2024-03-23T21:00:04.715-0300] {taskinstance.py:1518} INFO - Exporting the following env vars:
AIRFLOW_CTX_DAG_OWNER=falcone
AIRFLOW_CTX_DAG_ID=cross_task_communication2
AIRFLOW_CTX_TASK_ID=increment_by_1
AIRFLOW_CTX_EXECUTION_DATE=2024-03-23T00:00:00+00:00
AIRFLOW_CTX_TRY_NUMBER=1
AIRFLOW_CTX_DAG_RUN_ID=scheduled__2024-03-23T00:00:00+00:00
[2024-03-23T21:00:04.716-0300] {taskinstance.py:1776} ERROR - Task failed with exception
Traceback (most recent call last):
  File "/home/carlosfalcone/.local/lib/python3.7/site-packages/airflow/operators/python.py", line 175, in execute
    return_value = self.execute_callable()
  File "/home/carlosfalcone/.local/lib/python3.7/site-packages/airflow/operators/python.py", line 192, in execute_callable
    return self.python_callable(*self.op_args, **self.op_kwargs)
TypeError: increment_by_1() missing 1 required positional argument: 'value'
[2024-03-23T21:00:04.718-0300] {taskinstance.py:1332} INFO - Marking task as FAILED. dag_id=cross_task_communication2, task_id=increment_by_1, execution_date=20240323T000000, start_date=20240324T000004, end_date=20240324T000004
[2024-03-23T21:00:04.728-0300] {standard_task_runner.py:105} ERROR - Failed to execute job 99 for task increment_by_1 (increment_by_1() missing 1 required positional argument: 'value'; 7469)
[2024-03-23T21:00:04.734-0300] {local_task_job.py:212} INFO - Task exited with return code 1
[2024-03-23T21:00:04.747-0300] {taskinstance.py:2596} INFO - 0 downstream tasks scheduled from follow-on schedule check
