[2024-03-21T20:21:29.818-0300] {taskinstance.py:1090} INFO - Dependencies all met for dep_context=non-requeueable deps ti=<TaskInstance: execute_python_operators2.task_b scheduled__2024-03-20T00:00:00+00:00 [queued]>
[2024-03-21T20:21:29.823-0300] {taskinstance.py:1090} INFO - Dependencies all met for dep_context=requeueable deps ti=<TaskInstance: execute_python_operators2.task_b scheduled__2024-03-20T00:00:00+00:00 [queued]>
[2024-03-21T20:21:29.823-0300] {taskinstance.py:1288} INFO - 
--------------------------------------------------------------------------------
[2024-03-21T20:21:29.823-0300] {taskinstance.py:1289} INFO - Starting attempt 1 of 1
[2024-03-21T20:21:29.823-0300] {taskinstance.py:1290} INFO - 
--------------------------------------------------------------------------------
[2024-03-21T20:21:29.834-0300] {taskinstance.py:1309} INFO - Executing <Task(PythonOperator): task_b> on 2024-03-20 00:00:00+00:00
[2024-03-21T20:21:29.836-0300] {standard_task_runner.py:55} INFO - Started process 6682 to run task
[2024-03-21T20:21:29.838-0300] {standard_task_runner.py:82} INFO - Running: ['airflow', 'tasks', 'run', 'execute_python_operators2', 'task_b', 'scheduled__2024-03-20T00:00:00+00:00', '--job-id', '57', '--raw', '--subdir', 'DAGS_FOLDER/python_operators2.py', '--cfg-path', '/tmp/tmpk88utcyu']
[2024-03-21T20:21:29.839-0300] {standard_task_runner.py:83} INFO - Job 57: Subtask task_b
[2024-03-21T20:21:29.870-0300] {task_command.py:389} INFO - Running <TaskInstance: execute_python_operators2.task_b scheduled__2024-03-20T00:00:00+00:00 [running]> on host DESKTOP-0DNP0LN.localdomain
[2024-03-21T20:21:29.912-0300] {taskinstance.py:1518} INFO - Exporting the following env vars:
AIRFLOW_CTX_DAG_OWNER=falcone
AIRFLOW_CTX_DAG_ID=execute_python_operators2
AIRFLOW_CTX_TASK_ID=task_b
AIRFLOW_CTX_EXECUTION_DATE=2024-03-20T00:00:00+00:00
AIRFLOW_CTX_TRY_NUMBER=1
AIRFLOW_CTX_DAG_RUN_ID=scheduled__2024-03-20T00:00:00+00:00
[2024-03-21T20:21:29.913-0300] {taskinstance.py:1776} ERROR - Task failed with exception
Traceback (most recent call last):
  File "/home/carlosfalcone/.local/lib/python3.7/site-packages/airflow/operators/python.py", line 175, in execute
    return_value = self.execute_callable()
  File "/home/carlosfalcone/.local/lib/python3.7/site-packages/airflow/operators/python.py", line 192, in execute_callable
    return self.python_callable(*self.op_args, **self.op_kwargs)
  File "/home/carlosfalcone/airflow/dags/python_operators2.py", line 12, in task_b
    time.sleep(3)
NameError: name 'time' is not defined
[2024-03-21T20:21:29.915-0300] {taskinstance.py:1332} INFO - Marking task as FAILED. dag_id=execute_python_operators2, task_id=task_b, execution_date=20240320T000000, start_date=20240321T232129, end_date=20240321T232129
[2024-03-21T20:21:29.924-0300] {standard_task_runner.py:105} ERROR - Failed to execute job 57 for task task_b (name 'time' is not defined; 6682)
[2024-03-21T20:21:29.929-0300] {local_task_job.py:212} INFO - Task exited with return code 1
[2024-03-21T20:21:29.941-0300] {taskinstance.py:2596} INFO - 0 downstream tasks scheduled from follow-on schedule check
